Workbook

Sheet Inicio
B2: Informacion Basica para el Flujograma Vehicular
U3: N | V3: Tipo de Vehiculo | W3: UCP
D4: Código | F4: : | J4: Ubicación | K4: Link de google maps | U4: 1 | V4: Auto | W4: 1
D5: Intersección | F5: : | U5: 2 | V5: Moto | W5: 0.33
D6: Fecha | F6: : | G6: 45658 | U6: 3 | V6: Bus | W6: 3
D7: Mes | F7: : | G7: =UPPER(TEXT(G6,"mmmm")) | U7: 4 | V7: Camion | W7: 2.5
D8: Día | F8: : | G8: =UPPER(TEXT(G6,"dddd")) | U8: 5 | V8: Bicicleta | W8: 0.33
D9: Distrito | F9: : | U9: 6 | V9: Taxi | W9: 1
C10: Informaciòn de Los Accesos, Giros y Sentido | U10: 7 | V10: Van | W10: 2
E11: Origen | F11: Destino | G11: Giro | H11: Acceso | I11: Sentido | K11: Origen | L11: Destino | M11: Giro | N11: Acceso | O11: Sentido | U11: 8 | V11: Combi | W11: 2.5
I12: Norte | O12: Sur | U12: 9 | V12: Microbus | W12: 3
I13: Norte | O13: Sur | U13: 10 | V13: Mototaxi | W13: 0.5
I14: Norte | O14: Sur | U14: 11 | V14: Semi-trailer | W14: 4
I15: Norte | O15: Sur | U15: 12 | V15: Otros | W15: 1
I16: Norte | O16: Sur
I17: Norte | O17: Sur
I18: Norte | O18: Sur
I19: Norte | O19: Sur
I20: Norte | O20: Sur
I21: Norte | O21: Sur
E23: Origen | F23: Destino | G23: Giro | H23: Acceso | I23: Sentido | K23: Origen | L23: Destino | M23: Giro | N23: Acceso | O23: Sentido
E24: L1 | F24: L2 | G24: M1 | H24: Línea de conteo 1 | I24: Este | K24: L3 | L24: L4 | M24: M2 | N24: Línea de conteo 3 | O24: Oeste
I25: Este | O25: Oeste
I26: Este | O26: Oeste
I27: Este | O27: Oeste
I28: Este | O28: Oeste
I29: Este | O29: Oeste
I30: Este | O30: Oeste
I31: Este | O31: Oeste
I32: Este | O32: Oeste
I33: Este | O33: Oeste

Sheet HPMAD
E2: FLUJOGRAMA VEHICULAR DIRECCIONAL
AZ3: Metadatos
E4: Intersección: | F4: =Inicio!G5 | AQ4: Distrito: | AS4: =Inicio!G9 | AZ4: Fila HP: | BA4: =_xlfn.LET( _xlpm.rango, INDIRECT("N!EJ" & $BA$8 & ":EJ" & BA9), MATCH(MAX(_xlpm.rango),_xlpm.rango,0) )
E5: Fecha: | F5: =Inicio!G6 | AQ5: Turno: | AS5: Madrugada | AZ5: Fin: | BA5: =TIME(0,15,0)*BA4+TIME((BA8-9)/4,0,0)
E6: Día: | F6: =Inicio!G8 | AQ6: Hora Punta: | AS6: =BA7 | AZ6: Inicio: | BA6: =TIME(0,15,0)*(BA4-4)+TIME((BA8-9)/4,0,0)
E7: Volumen: | AQ7: Volumen UCP: | AZ7: HP: | BA7: =TEXT(BA6, "[hh]:mm") & " - " & TEXT(BA5, "[hh]:mm")
AZ8: Fila Inicio | BA8: 9
AZ9: Fila Fin | BA9: 32
E70: DISTRIBUCIÓN DE VOLUMEN POR GIRO, SENTIDO Y TIPOLOGÍA
F72: 1 | G72: 2 | H72: 3 | I72: 4 | J72: 5 | K72: 6 | L72: 7 | M72: 8 | N72: 9 | O72: 10 | P72: 1 | Q72: 2 | R72: 3 | S72: 4 | T72: 5 | U72: 6 | V72: 7 | W72: 8 | X72: 9 | Y72: 10 | Z72: 1 | AA72: 2 | AB72: 3 | AC72: 4 | AD72: 5 | AE72: 6 | AF72: 7 | AG72: 8 | AH72: 9 | AI72: 10 | AJ72: 1 | AK72: 2 | AL72: 3 | AM72: 4 | AN72: 5 | AO72: 6 | AP72: 7 | AQ72: 8 | AR72: 9 | AS72: 10
E73: Tipo de Vehículo | F73: =Inicio!$H$12 | P73: =Inicio!$H$12 | Z73: =Inicio!$H$12 | AJ73: =Inicio!$H$12 | AT73: Total | AU73: %
F74: Norte | P74: Sur | Z74: Este | AJ74: Oeste
D75: 0 | F75: =Inicio!$G$12 | G75: =Inicio!$G$13 | H75: =Inicio!$G$14 | I75: =Inicio!$G$15 | J75: =Inicio!$G$16 | K75: =Inicio!$G$17 | L75: =Inicio!$G$18 | M75: =Inicio!$G$19 | N75: =Inicio!$G$20 | O75: =Inicio!$G$21 | P75: =Inicio!$M$12 | Q75: =Inicio!$M$13 | R75: =Inicio!$M$14 | S75: =Inicio!$M$15 | T75: =Inicio!$M$16 | U75: =Inicio!$M$17 | V75: =Inicio!$M$18 | W75: =Inicio!$M$19 | X75: =Inicio!$M$20 | Y75: =Inicio!$M$21 | Z75: =Inicio!$G$24 | AA75: =Inicio!$G$25 | AB75: =Inicio!$G$26 | AC75: =Inicio!$G$27 | AD75: =Inicio!$G$28 | AE75: =Inicio!$G$29 | AF75: =Inicio!$G$30 | AG75: =Inicio!$G$31 | AH75: =Inicio!$G$32 | AI75: =Inicio!$G$33 | AJ75: =Inicio!$M$24 | AK75: =Inicio!$M$25 | AL75: =Inicio!$M$26 | AM75: =Inicio!$M$27 | AN75: =Inicio!$M$28 | AO75: =Inicio!$M$29 | AP75: =Inicio!$M$30 | AQ75: =Inicio!$M$31 | AR75: =Inicio!$M$32 | AS75: =Inicio!$M$33
D76: 1 | E76: =Inicio!V4 | F76: {=_xlfn.LET( _xlpm.rango, INDIRECT("N!$C$" & $BA$8 & ":$DR$" & $BA$9), _xlpm.col, F$72+$D75*10, INDEX(_xlpm.rango,$BA$4-3,_xlpm.col) + INDEX(_xlpm.rango,$BA$4-2,_xlpm.col) + INDEX(_xlpm.rango,$BA$4-1,_xlpm.col) + INDEX(_xlpm.rango,$BA$4, _xlpm.col) )} | G76: {=_xlfn.LET( _xlpm.rango, INDIRECT("N!$C$" & $BA$8 & ":$DR$" & $BA$9), _xlpm.col, G$72+$D75*10, INDEX(_xlpm.rango,$BA$4-3,_xlpm.col) + INDEX(_xlpm.rango,$BA$4-2,_xlpm.col) + INDEX(_xlpm.rango,$BA$4-1,_xlpm.col) + INDEX(_xlpm.rango,$BA$4, _xlpm.col) )} | H76: {=_xlfn.LET( _xlpm.rango, INDIRECT("N!$C$" & $BA$8 & ":$DR$" & $BA$9), _xlpm.col, H$72+$D75*10, INDEX(_xlpm.rango,$BA$4-3,_xlpm.col) + INDEX(_xlpm.rango,$BA$4-2,_xlpm.col) + INDEX(_xlpm.rango,$BA$4-1,_xlpm.col) + INDEX(_xlpm.rango,$BA$4, _xlpm.col) )} | I76: {=_xlfn.LET( _xlpm.rango, INDIRECT("N!$C$" & $BA$8 & ":$DR$" & $BA$9), _xlpm.col, I$72+$D75*10, INDEX(_xlpm.rango,$BA$4-3,_xlpm.col) + INDEX(_xlpm.rango,$BA$4-2,_xlpm.col) + INDEX(_xlpm.rango,$BA$4-1,_xlpm.col) + INDEX(_xlpm.rango,$BA$4, _xlpm.col) )} | J76: {=_xlfn.LET( _xlpm.rango, INDIRECT("N!$C$" & $BA$8 & ":$DR$" & $BA$9), _xlpm.col, J$72+$D75*10, INDEX(_xlpm.rango,$BA$4-3,_xlpm.col) + INDEX(_xlpm.rango,$BA$4-2,_xlpm.col) + INDEX(_xlpm.rango,$BA$4-1,_xlpm.col) + INDEX(_xlpm.rango,$BA$4, _xlpm.col) )} | K76: {=_xlfn.LET( _xlpm.rango, INDIRECT("N!$C$" & $BA$8 & ":$DR$" & $BA$9), _xlpm.col, K$72+$D75*10, INDEX(_xlpm.rango,$BA$4-3,_xlpm.col) + INDEX(_xlpm.rango,$BA$4-2,_xlpm.col) + INDEX(_xlpm.rango,$BA$4-1,_xlpm.col) + INDEX(_xlpm.rango,$BA$4, _xlpm.col) )} | L76: {=_xlfn.LET( _xlpm.rango, INDIRECT("N!$C$" & $BA$8 & ":$DR$" & $BA$9), _xlpm.col, L$72+$D75*10, INDEX(_xlpm.rango,$BA$4-3,_xlpm.col) + INDEX(_xlpm.rango,$BA$4-2,_xlpm.col) + INDEX(_xlpm.rango,$BA$4-1,_xlpm.col) + INDEX(_xlpm.rango,$BA$4, _xlpm.col) )} | M76: {=_xlfn.LET( _xlpm.rango, INDIRECT("N!$C$" & $BA$8 & ":$DR$" & $BA$9), _xlpm.col, M$72+$D75*10, INDEX(_xlpm.rango,$BA$4-3,_xlpm.col) + INDEX(_xlpm.rango,$BA$4-2,_xlpm.col) + INDEX(_xlpm.rango,$BA$4-1,_xlpm.col) + INDEX(_xlpm.rango,$BA$4, _xlpm.col) )} | ... O76: {=_xlfn.LET( _xlpm.rango, INDIRECT("N!$C$" & $BA$8 & ":$DR$" & $BA$9), _xlpm.col, O$72+$D75*10, INDEX(_xlpm.rango,$BA$4-3,_xlpm.col) + INDEX(_xlpm.rango,$BA$4-2,_xlpm.col) + INDEX(_xlpm.rango,$BA$4-1,_xlpm.col) + INDEX(_xlpm.rango,$BA$4, _xlpm.col) )} | P76: {=_xlfn.LET( _xlpm.rango, INDIRECT("S!$C$" & $BA$8 & ":$DR$" & $BA$9), _xlpm.col, P$72+$D75*10, INDEX(_xlpm.rango,$BA$4-3,_xlpm.col) + INDEX(_xlpm.rango,$BA$4-2,_xlpm.col) + INDEX(_xlpm.rango,$BA$4-1,_xlpm.col) + INDEX(_xlpm.rango,$BA$4, _xlpm.col) )} | Q76: {=_xlfn.LET( _xlpm.rango, INDIRECT("S!$C$" & $BA$8 & ":$DR$" & $BA$9), _xlpm.col, Q$72+$D75*10, INDEX(_xlpm.rango,$BA$4-3,_xlpm.col) + INDEX(_xlpm.rango,$BA$4-2,_xlpm.col) + INDEX(_xlpm.rango,$BA$4-1,_xlpm.col) + INDEX(_xlpm.rango,$BA$4, _xlpm.col) )} | R76: {=_xlfn.LET( _xlpm.rango, INDIRECT("S!$C$" & $BA$8 & ":$DR$" & $BA$9), _xlpm.col, R$72+$D75*10, INDEX(_xlpm.rango,$BA$4-3,_xlpm.col) + INDEX(_xlpm.rango,$BA$4-2,_xlpm.col) + INDEX(_xlpm.rango,$BA$4-1,_xlpm.col) + INDEX(_xlpm.rango,$BA$4, _xlpm.col) )} | S76: {=_xlfn.LET( _xlpm.rango, INDIRECT("S!$C$" & $BA$8 & ":$DR$" & $BA$9), _xlpm.col, S$72+$D75*10, INDEX(_xlpm.rango,$BA$4-3,_xlpm.col) + INDEX(_xlpm.rango,$BA$4-2,_xlpm.col) + INDEX(_xlpm.rango,$BA$4-1,_xlpm.col) + INDEX(_xlpm.rango,$BA$4, _xlpm.col) )} | T76: {=_xlfn.LET( _xlpm.rango, INDIRECT("S!$C$" & $BA$8 & ":$DR$" & $BA$9), _xlpm.col, T$72+$D75*10, INDEX(_xlpm.rango,$BA$4-3,_xlpm.col) + INDEX(_xlpm.rango,$BA$4-2,_xlpm.col) + INDEX(_xlpm.rango,$BA$4-1,_xlpm.col) + INDEX(_xlpm.rango,$BA$4, _xlpm.col) )} | U76: {=_xlfn.LET( _xlpm.rango, INDIRECT("S!$C$" & $BA$8 & ":$DR$" & $BA$9), _xlpm.col, U$72+$D75*10, INDEX(_xlpm.rango,$BA$4-3,_xlpm.col) + INDEX(_xlpm.rango,$BA$4-2,_xlpm.col) + INDEX(_xlpm.rango,$BA$4-1,_xlpm.col) + INDEX(_xlpm.rango,$BA$4, _xlpm.col) )} | V76: {=_xlfn.LET( _xlpm.rango, INDIRECT("S!$C$" & $BA$8 & ":$DR$" & $BA$9), _xlpm.col, V$72+$D75*10, INDEX(_xlpm.rango,$BA$4-3,_xlpm.col) + INDEX(_xlpm.rango,$BA$4-2,_xlpm.col) + INDEX(_xlpm.rango,$BA$4-1,_xlpm.col) + INDEX(_xlpm.rango,$BA$4, _xlpm.col) )} | W76: {=_xlfn.LET( _xlpm.rango, INDIRECT("S!$C$" & $BA$8 & ":$DR$" & $BA$9), _xlpm.col, W$72+$D75*10, INDEX(_xlpm.rango,$BA$4-3,_xlpm.col) + INDEX(_xlpm.rango,$BA$4-2,_xlpm.col) + INDEX(_xlpm.rango,$BA$4-1,_xlpm.col) + INDEX(_xlpm.rango,$BA$4, _xlpm.col) )} | ... Y76: {=_xlfn.LET( _xlpm.rango, INDIRECT("S!$C$" & $BA$8 & ":$DR$" & $BA$9), _xlpm.col, Y$72+$D75*10, INDEX(_xlpm.rango,$BA$4-3,_xlpm.col) + INDEX(_xlpm.rango,$BA$4-2,_xlpm.col) + INDEX(_xlpm.rango,$BA$4-1,_xlpm.col) + INDEX(_xlpm.rango,$BA$4, _xlpm.col) )} | Z76: {=_xlfn.LET( _xlpm.rango, INDIRECT("E!$C$" & $BA$8 & ":$DR$" & $BA$9), _xlpm.col, Z$72+$D75*10, INDEX(_xlpm.rango,$BA$4-3,_xlpm.col) + INDEX(_xlpm.rango,$BA$4-2,_xlpm.col) + INDEX(_xlpm.rango,$BA$4-1,_xlpm.col) + INDEX(_xlpm.rango,$BA$4, _xlpm.col) )} | AA76: {=_xlfn.LET( _xlpm.rango, INDIRECT("E!$C$" & $BA$8 & ":$DR$" & $BA$9), _xlpm.col, AA$72+$D75*10, INDEX(_xlpm.rango,$BA$4-3,_xlpm.col) + INDEX(_xlpm.rango,$BA$4-2,_xlpm.col) + INDEX(_xlpm.rango,$BA$4-1,_xlpm.col) + INDEX(_xlpm.rango,$BA$4, _xlpm.col) )} | AB76: {=_xlfn.LET( _xlpm.rango, INDIRECT("E!$C$" & $BA$8 & ":$DR$" & $BA$9), _xlpm.col, AB$72+$D75*10, INDEX(_xlpm.rango,$BA$4-3,_xlpm.col) + INDEX(_xlpm.rango,$BA$4-2,_xlpm.col) + INDEX(_xlpm.rango,$BA$4-1,_xlpm.col) + INDEX(_xlpm.rango,$BA$4, _xlpm.col) )} | AC76: {=_xlfn.LET( _xlpm.rango, INDIRECT("E!$C$" & $BA$8 & ":$DR$" & $BA$9), _xlpm.col, AC$72+$D75*10, INDEX(_xlpm.rango,$BA$4-3,_xlpm.col) + INDEX(_xlpm.rango,$BA$4-2,_xlpm.col) + INDEX(_xlpm.rango,$BA$4-1,_xlpm.col) + INDEX(_xlpm.rango,$BA$4, _xlpm.col) )} | AD76: {=_xlfn.LET( _xlpm.rango, INDIRECT("E!$C$" & $BA$8 & ":$DR$" & $BA$9), _xlpm.col, AD$72+$D75*10, INDEX(_xlpm.rango,$BA$4-3,_xlpm.col) + INDEX(_xlpm.rango,$BA$4-2,_xlpm.col) + INDEX(_xlpm.rango,$BA$4-1,_xlpm.col) + INDEX(_xlpm.rango,$BA$4, _xlpm.col) )} | AE76: {=_xlfn.LET( _xlpm.rango, INDIRECT("E!$C$" & $BA$8 & ":$DR$" & $BA$9), _xlpm.col, AE$72+$D75*10, INDEX(_xlpm.rango,$BA$4-3,_xlpm.col) + INDEX(_xlpm.rango,$BA$4-2,_xlpm.col) + INDEX(_xlpm.rango,$BA$4-1,_xlpm.col) + INDEX(_xlpm.rango,$BA$4, _xlpm.col) )} | AF76: {=_xlfn.LET( _xlpm.rango, INDIRECT("E!$C$" & $BA$8 & ":$DR$" & $BA$9), _xlpm.col, AF$72+$D75*10, INDEX(_xlpm.rango,$BA$4-3,_xlpm.col) + INDEX(_xlpm.rango,$BA$4-2,_xlpm.col) + INDEX(_xlpm.rango,$BA$4-1,_xlpm.col) + INDEX(_xlpm.rango,$BA$4, _xlpm.col) )} | AG76: {=_xlfn.LET( _xlpm.rango, INDIRECT("E!$C$" & $BA$8 & ":$DR$" & $BA$9), _xlpm.col, AG$72+$D75*10, INDEX(_xlpm.rango,$BA$4-3,_xlpm.col) + INDEX(_xlpm.rango,$BA$4-2,_xlpm.col) + INDEX(_xlpm.rango,$BA$4-1,_xlpm.col) + INDEX(_xlpm.rango,$BA$4, _xlpm.col) )} | ... AS76: {=_xlfn.LET( _xlpm.rango, INDIRECT("E!$C$" & $BA$8 & ":$DR$" & $BA$9), _xlpm.col, AS$72+$D75*10, INDEX(_xlpm.rango,$BA$4-3,_xlpm.col) + INDEX(_xlpm.rango,$BA$4-2,_xlpm.col) + INDEX(_xlpm.rango,$BA$4-1,_xlpm.col) + INDEX(_xlpm.rango,$BA$4, _xlpm.col) )} | AT76: =SUM(F76:AS76) | AU76: =AT76/$AT$88
D77: 2 | E77: =Inicio!V5 | F77: {=_xlfn.LET( _xlpm.rango, INDIRECT("N!$C$" & $BA$8 & ":$DR$" & $BA$9), _xlpm.col, F$72+$D76*10, INDEX(_xlpm.rango,$BA$4-3,_xlpm.col) + INDEX(_xlpm.rango,$BA$4-2,_xlpm.col) + INDEX(_xlpm.rango,$BA$4-1,_xlpm.col) + INDEX(_xlpm.rango,$BA$4, _xlpm.col) )} | G77: {=_xlfn.LET( _xlpm.rango, INDIRECT("N!$C$" & $BA$8 & ":$DR$" & $BA$9), _xlpm.col, G$72+$D76*10, INDEX(_xlpm.rango,$BA$4-3,_xlpm.col) + INDEX(_xlpm.rango,$BA$4-2,_xlpm.col) + INDEX(_xlpm.rango,$BA$4-1,_xlpm.col) + INDEX(_xlpm.rango,$BA$4, _xlpm.col) )} | H77: {=_xlfn.LET( _xlpm.rango, INDIRECT("N!$C$" & $BA$8 & ":$DR$" & $BA$9), _xlpm.col, H$72+$D76*10, INDEX(_xlpm.rango,$BA$4-3,_xlpm.col) + INDEX(_xlpm.rango,$BA$4-2,_xlpm.col) + INDEX(_xlpm.rango,$BA$4-1,_xlpm.col) + INDEX(_xlpm.rango,$BA$4, _xlpm.col) )} | I77: {=_xlfn.LET( _xlpm.rango, INDIRECT("N!$C$" & $BA$8 & ":$DR$" & $BA$9), _xlpm.col, I$72+$D76*10, INDEX(_xlpm.rango,$BA$4-3,_xlpm.col) + INDEX(_xlpm.rango,$BA$4-2,_xlpm.col) + INDEX(_xlpm.rango,$BA$4-1,_xlpm.col) + INDEX(_xlpm.rango,$BA$4, _xlpm.col) )} | J77: {=_xlfn.LET( _xlpm.rango, INDIRECT("N!$C$" & $BA$8 & ":$DR$" & $BA$9), _xlpm.col, J$72+$D76*10, INDEX(_xlpm.rango,$BA$4-3,_xlpm.col) + INDEX(_xlpm.rango,$BA$4-2,_xlpm.col) + INDEX(_xlpm.rango,$BA$4-1,_xlpm.col) + INDEX(_xlpm.rango,$BA$4, _xlpm.col) )} | K77: {=_xlfn.LET( _xlpm.rango, INDIRECT("N!$C$" & $BA$8 & ":$DR$" & $BA$9), _xlpm.col, K$72+$D76*10, INDEX(_xlpm.rango,$BA$4-3,_xlpm.col) + INDEX(_xlpm.rango,$BA$4-2,_xlpm.col) + INDEX(_xlpm.rango,$BA$4-1,_xlpm.col) + INDEX(_xlpm.rango,$BA$4, _xlpm.col) )} | L77: {=_xlfn.LET( _xlpm.rango, INDIRECT("N!$C$" & $BA$8 & ":$DR$" & $BA$9), _xlpm.col, L$72+$D76*10, INDEX(_xlpm.rango,$BA$4-3,_xlpm.col) + INDEX(_xlpm.rango,$BA$4-2,_xlpm.col) + INDEX(_xlpm.rango,$BA$4-1,_xlpm.col) + INDEX(_xlpm.rango,$BA$4, _xlpm.col) )} | M77: {=_xlfn.LET( _xlpm.rango, INDIRECT("N!$C$" & $BA$8 & ":$DR$" & $BA$9), _xlpm.col, M$72+$D76*10, INDEX(_xlpm.rango,$BA$4-3,_xlpm.col) + INDEX(_xlpm.rango,$BA$4-2,_xlpm.col) + INDEX(_xlpm.rango,$BA$4-1,_xlpm.col) + INDEX(_xlpm.rango,$BA$4, _xlpm.col) )} | ... O77: {=_xlfn.LET( _xlpm.rango, INDIRECT("N!$C$" & $BA$8 & ":$DR$" & $BA$9), _xlpm.col, O$72+$D76*10, INDEX(_xlpm.rango,$BA$4-3,_xlpm.col) + INDEX(_xlpm.rango,$BA$4-2,_xlpm.col) + INDEX(_xlpm.rango,$BA$4-1,_xlpm.col) + INDEX(_xlpm.rango,$BA$4, _xlpm.col) )} | P77: {=_xlfn.LET( _xlpm.rango, INDIRECT("S!$C$" & $BA$8 & ":$DR$" & $BA$9), _xlpm.col, P$72+$D76*10, INDEX(_xlpm.rango,$BA$4-3,_xlpm.col) + INDEX(_xlpm.rango,$BA$4-2,_xlpm.col) + INDEX(_xlpm.rango,$BA$4-1,_xlpm.col) + INDEX(_xlpm.rango,$BA$4, _xlpm.col) )} | Q77: {=_xlfn.LET( _xlpm.rango, INDIRECT("S!$C$" & $BA$8 & ":$DR$" & $BA$9), _xlpm.col, Q$72+$D76*10, INDEX(_xlpm.rango,$BA$4-3,_xlpm.col) + INDEX(_xlpm.rango,$BA$4-2,_xlpm.col) + INDEX(_xlpm.rango,$BA$4-1,_xlpm.col) + INDEX(_xlpm.rango,$BA$4, _xlpm.col) )} | R77: {=_xlfn.LET( _xlpm.rango, INDIRECT("S!$C$" & $BA$8 & ":$DR$" & $BA$9), _xlpm.col, R$72+$D76*10, INDEX(_xlpm.rango,$BA$4-3,_xlpm.col) + INDEX(_xlpm.rango,$BA$4-2,_xlpm.col) + INDEX(_xlpm.rango,$BA$4-1,_xlpm.col) + INDEX(_xlpm.rango,$BA$4, _xlpm.col) )} | S77: {=_xlfn.LET( _xlpm.rango, INDIRECT("S!$C$" & $BA$8 & ":$DR$" & $BA$9), _xlpm.col, S$72+$D76*10, INDEX(_xlpm.rango,$BA$4-3,_xlpm.col) + INDEX(_xlpm.rango,$BA$4-2,_xlpm.col) + INDEX(_xlpm.rango,$BA$4-1,_xlpm.col) + INDEX(_xlpm.rango,$BA$4, _xlpm.col) )} | T77: {=_xlfn.LET( _xlpm.rango, INDIRECT("S!$C$" & $BA$8 & ":$DR$" & $BA$9), _xlpm.col, T$72+$D76*10, INDEX(_xlpm.rango,$BA$4-3,_xlpm.col) + INDEX(_xlpm.rango,$BA$4-2,_xlpm.col) + INDEX(_xlpm.rango,$BA$4-1,_xlpm.col) + INDEX(_xlpm.rango,$BA$4, _xlpm.col) )} | U77: {=_xlfn.LET( _xlpm.rango, INDIRECT("S!$C$" & $BA$8 & ":$DR$" & $BA$9), _xlpm.col, U$72+$D76*10, INDEX(_xlpm.rango,$BA$4-3,_xlpm.col) + INDEX(_xlpm.rango,$BA$4-2,_xlpm.col) + INDEX(_xlpm.rango,$BA$4-1,_xlpm.col) + INDEX(_xlpm.rango,$BA$4, _xlpm.col) )} | V77: {=_xlfn.LET( _xlpm.rango, INDIRECT("S!$C$" & $BA$8 & ":$DR$" & $BA$9), _xlpm.col, V$72+$D76*10, INDEX(_xlpm.rango,$BA$4-3,_xlpm.col) + INDEX(_xlpm.rango,$BA$4-2,_xlpm.col) + INDEX(_xlpm.rango,$BA$4-1,_xlpm.col) + INDEX(_xlpm.rango,$BA$4, _xlpm.col) )} | W77: {=_xlfn.LET( _xlpm.rango, INDIRECT("S!$C$" & $BA$8 & ":$DR$" & $BA$9), _xlpm.col, W$72+$D76*10, INDEX(_xlpm.rango,$BA$4-3,_xlpm.col) + INDEX(_xlpm.rango,$BA$4-2,_xlpm.col) + INDEX(_xlpm.rango,$BA$4-1,_xlpm.col) + INDEX(_xlpm.rango,$BA$4, _xlpm.col) )} | ... Y77: {=_xlfn.LET( _xlpm.rango, INDIRECT("S!$C$" & $BA$8 & ":$DR$" & $BA$9), _xlpm.col, Y$72+$D76*10, INDEX(_xlpm.rango,$BA$4-3,_xlpm.col) + INDEX(_xlpm.rango,$BA$4-2,_xlpm.col) + INDEX(_xlpm.rango,$BA$4-1,_xlpm.col) + INDEX(_xlpm.rango,$BA$4, _xlpm.col) )} | Z77: {=_xlfn.LET( _xlpm.rango, INDIRECT("E!$C$" & $BA$8 & ":$DR$" & $BA$9), _xlpm.col, Z$72+$D76*10, INDEX(_xlpm.rango,$BA$4-3,_xlpm.col) + INDEX(_xlpm.rango,$BA$4-2,_xlpm.col) + INDEX(_xlpm.rango,$BA$4-1,_xlpm.col) + INDEX(_xlpm.rango,$BA$4, _xlpm.col) )} | AA77: {=_xlfn.LET( _xlpm.rango, INDIRECT("E!$C$" & $BA$8 & ":$DR$" & $BA$9), _xlpm.col, AA$72+$D76*10, INDEX(_xlpm.rango,$BA$4-3,_xlpm.col) + INDEX(_xlpm.rango,$BA$4-2,_xlpm.col) + INDEX(_xlpm.rango,$BA$4-1,_xlpm.col) + INDEX(_xlpm.rango,$BA$4, _xlpm.col) )} | AB77: {=_xlfn.LET( _xlpm.rango, INDIRECT("E!$C$" & $BA$8 & ":$DR$" & $BA$9), _xlpm.col, AB$72+$D76*10, INDEX(_xlpm.rango,$BA$4-3,_xlpm.col) + INDEX(_xlpm.rango,$BA$4-2,_xlpm.col) + INDEX(_xlpm.rango,$BA$4-1,_xlpm.col) + INDEX(_xlpm.rango,$BA$4, _xlpm.col) )} | AC77: {=_xlfn.LET( _xlpm.rango, INDIRECT("E!$C$" & $BA$8 & ":$DR$" & $BA$9), _xlpm.col, AC$72+$D76*10, INDEX(_xlpm.rango,$BA$4-3,_xlpm.col) + INDEX(_xlpm.rango,$BA$4-2,_xlpm.col) + INDEX(_xlpm.rango,$BA$4-1,_xlpm.col) + INDEX(_xlpm.rango,$BA$4, _xlpm.col) )} | AD77: {=_xlfn.LET( _xlpm.rango, INDIRECT("E!$C$" & $BA$8 & ":$DR$" & $BA$9), _xlpm.col, AD$72+$D76*10, INDEX(_xlpm.rango,$BA$4-3,_xlpm.col) + INDEX(_xlpm.rango,$BA$4-2,_xlpm.col) + INDEX(_xlpm.rango,$BA$4-1,_xlpm.col) + INDEX(_xlpm.rango,$BA$4, _xlpm.col) )} | AE77: {=_xlfn.LET( _xlpm.rango, INDIRECT("E!$C$" & $BA$8 & ":$DR$" & $BA$9), _xlpm.col, AE$72+$D76*10, INDEX(_xlpm.rango,$BA$4-3,_xlpm.col) + INDEX(_xlpm.rango,$BA$4-2,_xlpm.col) + INDEX(_xlpm.rango,$BA$4-1,_xlpm.col) + INDEX(_xlpm.rango,$BA$4, _xlpm.col) )} | AF77: {=_xlfn.LET( _xlpm.rango, INDIRECT("E!$C$" & $BA$8 & ":$DR$" & $BA$9), _xlpm.col, AF$72+$D76*10, INDEX(_xlpm.rango,$BA$4-3,_xlpm.col) + INDEX(_xlpm.rango,$BA$4-2,_xlpm.col) + INDEX(_xlpm.rango,$BA$4-1,_xlpm.col) + INDEX(_xlpm.rango,$BA$4, _xlpm.col) )} | AG77: {=_xlfn.LET( _xlpm.rango, INDIRECT("E!$C$" & $BA$8 & ":$DR$" & $BA$9), _xlpm.col, AG$72+$D76*10, INDEX(_xlpm.rango,$BA$4-3,_xlpm.col) + INDEX(_xlpm.rango,$BA$4-2,_xlpm.col) + INDEX(_xlpm.rango,$BA$4-1,_xlpm.col) + INDEX(_xlpm.rango,$BA$4, _xlpm.col) )} | ... AS77: {=_xlfn.LET( _xlpm.rango, INDIRECT("E!$C$" & $BA$8 & ":$DR$" & $BA$9), _xlpm.col, AS$72+$D76*10, INDEX(_xlpm.rango,$BA$4-3,_xlpm.col) + INDEX(_xlpm.rango,$BA$4-2,_xlpm.col) + INDEX(_xlpm.rango,$BA$4-1,_xlpm.col) + INDEX(_xlpm.rango,$BA$4, _xlpm.col) )} | AT77: =SUM(F77:AS77) | AU77: =AT77/$AT$88
D78: 3 | E78: =Inicio!V6 | F78: {=_xlfn.LET( _xlpm.rango, INDIRECT("N!$C$" & $BA$8 & ":$DR$" & $BA$9), _xlpm.col, F$72+$D77*10, INDEX(_xlpm.rango,$BA$4-3,_xlpm.col) + INDEX(_xlpm.rango,$BA$4-2,_xlpm.col) + INDEX(_xlpm.rango,$BA$4-1,_xlpm.col) + INDEX(_xlpm.rango,$BA$4, _xlpm.col) )} | G78: {=_xlfn.LET( _xlpm.rango, INDIRECT("N!$C$" & $BA$8 & ":$DR$" & $BA$9), _xlpm.col, G$72+$D77*10, INDEX(_xlpm.rango,$BA$4-3,_xlpm.col) + INDEX(_xlpm.rango,$BA$4-2,_xlpm.col) + INDEX(_xlpm.rango,$BA$4-1,_xlpm.col) + INDEX(_xlpm.rango,$BA$4, _xlpm.col) )} | H78: {=_xlfn.LET( _xlpm.rango, INDIRECT("N!$C$" & $BA$8 & ":$DR$" & $BA$9), _xlpm.col, H$72+$D77*10, INDEX(_xlpm.rango,$BA$4-3,_xlpm.col) + INDEX(_xlpm.rango,$BA$4-2,_xlpm.col) + INDEX(_xlpm.rango,$BA$4-1,_xlpm.col) + INDEX(_xlpm.rango,$BA$4, _xlpm.col) )} | I78: {=_xlfn.LET( _xlpm.rango, INDIRECT("N!$C$" & $BA$8 & ":$DR$" & $BA$9), _xlpm.col, I$72+$D77*10, INDEX(_xlpm.rango,$BA$4-3,_xlpm.col) + INDEX(_xlpm.rango,$BA$4-2,_xlpm.col) + INDEX(_xlpm.rango,$BA$4-1,_xlpm.col) + INDEX(_xlpm.rango,$BA$4, _xlpm.col) )} | J78: {=_xlfn.LET( _xlpm.rango, INDIRECT("N!$C$" & $BA$8 & ":$DR$" & $BA$9), _xlpm.col, J$72+$D77*10, INDEX(_xlpm.rango,$BA$4-3,_xlpm.col) + INDEX(_xlpm.rango,$BA$4-2,_xlpm.col) + INDEX(_xlpm.rango,$BA$4-1,_xlpm.col) + INDEX(_xlpm.rango,$BA$4, _xlpm.col) )} | K78: {=_xlfn.LET( _xlpm.rango, INDIRECT("N!$C$" & $BA$8 & ":$DR$" & $BA$9), _xlpm.col, K$72+$D77*10, INDEX(_xlpm.rango,$BA$4-3,_xlpm.col) + INDEX(_xlpm.rango,$BA$4-2,_xlpm.col) + INDEX(_xlpm.rango,$BA$4-1,_xlpm.col) + INDEX(_xlpm.rango,$BA$4, _xlpm.col) )} | L78: {=_xlfn.LET( _xlpm.rango, INDIRECT("N!$C$" & $BA$8 & ":$DR$" & $BA$9), _xlpm.col, L$72+$D77*10, INDEX(_xlpm.rango,$BA$4-3,_xlpm.col) + INDEX(_xlpm.rango,$BA$4-2,_xlpm.col) + INDEX(_xlpm.rango,$BA$4-1,_xlpm.col) + INDEX(_xlpm.rango,$BA$4, _xlpm.col) )} | M78: {=_xlfn.LET( _xlpm.rango, INDIRECT("N!$C$" & $BA$8 & ":$DR$" & $BA$9), _xlpm.col, M$72+$D77*10, INDEX(_xlpm.rango,$BA$4-3,_xlpm.col) + INDEX(_xlpm.rango,$BA$4-2,_xlpm.col) + INDEX(_xlpm.rango,$BA$4-1,_xlpm.col) + INDEX(_xlpm.rango,$BA$4, _xlpm.col) )} | ... O78: {=_xlfn.LET( _xlpm.rango, INDIRECT("N!$C$" & $BA$8 & ":$DR$" & $BA$9), _xlpm.col, O$72+$D77*10, INDEX(_xlpm.rango,$BA$4-3,_xlpm.col) + INDEX(_xlpm.rango,$BA$4-2,_xlpm.col) + INDEX(_xlpm.rango,$BA$4-1,_xlpm.col) + INDEX(_xlpm.rango,$BA$4, _xlpm.col) )} | P78: {=_xlfn.LET( _xlpm.rango, INDIRECT("S!$C$" & $BA$8 & ":$DR$" & $BA$9), _xlpm.col, P$72+$D77*10, INDEX(_xlpm.rango,$BA$4-3,_xlpm.col) + INDEX(_xlpm.rango,$BA$4-2,_xlpm.col) + INDEX(_xlpm.rango,$BA$4-1,_xlpm.col) + INDEX(_xlpm.rango,$BA$4, _xlpm.col) )} | Q78: {=_xlfn.LET( _xlpm.rango, INDIRECT("S!$C$" & $BA$8 & ":$DR$" & $BA$9), _xlpm.col, Q$72+$D77*10, INDEX(_xlpm.rango,$BA$4-3,_xlpm.col) + INDEX(_xlpm.rango,$BA$4-2,_xlpm.col) + INDEX(_xlpm.rango,$BA$4-1,_xlpm.col) + INDEX(_xlpm.rango,$BA$4, _xlpm.col) )} | R78: {=_xlfn.LET( _xlpm.rango, INDIRECT("S!$C$" & $BA$8 & ":$DR$" & $BA$9), _xlpm.col, R$72+$D77*10, INDEX(_xlpm.rango,$BA$4-3,_xlpm.col) + INDEX(_xlpm.rango,$BA$4-2,_xlpm.col) + INDEX(_xlpm.rango,$BA$4-1,_xlpm.col) + INDEX(_xlpm.rango,$BA$4, _xlpm.col) )} | S78: {=_xlfn.LET( _xlpm.rango, INDIRECT("S!$C$" & $BA$8 & ":$DR$" & $BA$9), _xlpm.col, S$72+$D77*10, INDEX(_xlpm.rango,$BA$4-3,_xlpm.col) + INDEX(_xlpm.rango,$BA$4-2,_xlpm.col) + INDEX(_xlpm.rango,$BA$4-1,_xlpm.col) + INDEX(_xlpm.rango,$BA$4, _xlpm.col) )} | T78: {=_xlfn.LET( _xlpm.rango, INDIRECT("S!$C$" & $BA$8 & ":$DR$" & $BA$9), _xlpm.col, T$72+$D77*10, INDEX(_xlpm.rango,$BA$4-3,_xlpm.col) + INDEX(_xlpm.rango,$BA$4-2,_xlpm.col) + INDEX(_xlpm.rango,$BA$4-1,_xlpm.col) + INDEX(_xlpm.rango,$BA$4, _xlpm.col) )} | U78: {=_xlfn.LET( _xlpm.rango, INDIRECT("S!$C$" & $BA$8 & ":$DR$" & $BA$9), _xlpm.col, U$72+$D77*10, INDEX(_xlpm.rango,$BA$4-3,_xlpm.col) + INDEX(_xlpm.rango,$BA$4-2,_xlpm.col) + INDEX(_xlpm.rango,$BA$4-1,_xlpm.col) + INDEX(_xlpm.rango,$BA$4, _xlpm.col) )} | V78: {=_xlfn.LET( _xlpm.rango, INDIRECT("S!$C$" & $BA$8 & ":$DR$" & $BA$9), _xlpm.col, V$72+$D77*10, INDEX(_xlpm.rango,$BA$4-3,_xlpm.col) + INDEX(_xlpm.rango,$BA$4-2,_xlpm.col) + INDEX(_xlpm.rango,$BA$4-1,_xlpm.col) + INDEX(_xlpm.rango,$BA$4, _xlpm.col) )} | W78: {=_xlfn.LET( _xlpm.rango, INDIRECT("S!$C$" & $BA$8 & ":$DR$" & $BA$9), _xlpm.col, W$72+$D77*10, INDEX(_xlpm.rango,$BA$4-3,_xlpm.col) + INDEX(_xlpm.rango,$BA$4-2,_xlpm.col) + INDEX(_xlpm.rango,$BA$4-1,_xlpm.col) + INDEX(_xlpm.rango,$BA$4, _xlpm.col) )} | ... Y78: {=_xlfn.LET( _xlpm.rango, INDIRECT("S!$C$" & $BA$8 & ":$DR$" & $BA$9), _xlpm.col, Y$72+$D77*10, INDEX(_xlpm.rango,$BA$4-3,_xlpm.col) + INDEX(_xlpm.rango,$BA$4-2,_xlpm.col) + INDEX(_xlpm.rango,$BA$4-1,_xlpm.col) + INDEX(_xlpm.rango,$BA$4, _xlpm.col) )} | Z78: {=_xlfn.LET( _xlpm.rango, INDIRECT("E!$C$" & $BA$8 & ":$DR$" & $BA$9), _xlpm.col, Z$72+$D77*10, INDEX(_xlpm.rango,$BA$4-3,_xlpm.col) + INDEX(_xlpm.rango,$BA$4-2,_xlpm.col) + INDEX(_xlpm.rango,$BA$4-1,_xlpm.col) + INDEX(_xlpm.rango,$BA$4, _xlpm.col) )} | AA78: {=_xlfn.LET( _xlpm.rango, INDIRECT("E!$C$" & $BA$8 & ":$DR$" & $BA$9), _xlpm.col, AA$72+$D77*10, INDEX(_xlpm.rango,$BA$4-3,_xlpm.col) + INDEX(_xlpm.rango,$BA$4-2,_xlpm.col) + INDEX(_xlpm.rango,$BA$4-1,_xlpm.col) + INDEX(_xlpm.rango,$BA$4, _xlpm.col) )} | AB78: {=_xlfn.LET( _xlpm.rango, INDIRECT("E!$C$" & $BA$8 & ":$DR$" & $BA$9), _xlpm.col, AB$72+$D77*10, INDEX(_xlpm.rango,$BA$4-3,_xlpm.col) + INDEX(_xlpm.rango,$BA$4-2,_xlpm.col) + INDEX(_xlpm.rango,$BA$4-1,_xlpm.col) + INDEX(_xlpm.rango,$BA$4, _xlpm.col) )} | AC78: {=_xlfn.LET( _xlpm.rango, INDIRECT("E!$C$" & $BA$8 & ":$DR$" & $BA$9), _xlpm.col, AC$72+$D77*10, INDEX(_xlpm.rango,$BA$4-3,_xlpm.col) + INDEX(_xlpm.rango,$BA$4-2,_xlpm.col) + INDEX(_xlpm.rango,$BA$4-1,_xlpm.col) + INDEX(_xlpm.rango,$BA$4, _xlpm.col) )} | AD78: {=_xlfn.LET( _xlpm.rango, INDIRECT("E!$C$" & $BA$8 & ":$DR$" & $BA$9), _xlpm.col, AD$72+$D77*10, INDEX(_xlpm.rango,$BA$4-3,_xlpm.col) + INDEX(_xlpm.rango,$BA$4-2,_xlpm.col) + INDEX(_xlpm.rango,$BA$4-1,_xlpm.col) + INDEX(_xlpm.rango,$BA$4, _xlpm.col) )} | AE78: {=_xlfn.LET( _xlpm.rango, INDIRECT("E!$C$" & $BA$8 & ":$DR$" & $BA$9), _xlpm.col, AE$72+$D77*10, INDEX(_xlpm.rango,$BA$4-3,_xlpm.col) + INDEX(_xlpm.rango,$BA$4-2,_xlpm.col) + INDEX(_xlpm.rango,$BA$4-1,_xlpm.col) + INDEX(_xlpm.rango,$BA$4, _xlpm.col) )} | AF78: {=_xlfn.LET( _xlpm.rango, INDIRECT("E!$C$" & $BA$8 & ":$DR$" & $BA$9), _xlpm.col, AF$72+$D77*10, INDEX(_xlpm.rango,$BA$4-3,_xlpm.col) + INDEX(_xlpm.rango,$BA$4-2,_xlpm.col) + INDEX(_xlpm.rango,$BA$4-1,_xlpm.col) + INDEX(_xlpm.rango,$BA$4, _xlpm.col) )} | AG78: {=_xlfn.LET( _xlpm.rango, INDIRECT("E!$C$" & $BA$8 & ":$DR$" & $BA$9), _xlpm.col, AG$72+$D77*10, INDEX(_xlpm.rango,$BA$4-3,_xlpm.col) + INDEX(_xlpm.rango,$BA$4-2,_xlpm.col) + INDEX(_xlpm.rango,$BA$4-1,_xlpm.col) + INDEX(_xlpm.rango,$BA$4, _xlpm.col) )} | ... AS78: {=_xlfn.LET( _xlpm.rango, INDIRECT("E!$C$" & $BA$8 & ":$DR$" & $BA$9), _xlpm.col, AS$72+$D77*10, INDEX(_xlpm.rango,$BA$4-3,_xlpm.col) + INDEX(_xlpm.rango,$BA$4-2,_xlpm.col) + INDEX(_xlpm.rango,$BA$4-1,_xlpm.col) + INDEX(_xlpm.rango,$BA$4, _xlpm.col) )} | AT78: =SUM(F78:AS78) | AU78: =AT78/$AT$88
D79: 4 | E79: =Inicio!V7 | F79: {=_xlfn.LET( _xlpm.rango, INDIRECT("N!$C$" & $BA$8 & ":$DR$" & $BA$9), _xlpm.col, F$72+$D78*10, INDEX(_xlpm.rango,$BA$4-3,_xlpm.col) + INDEX(_xlpm.rango,$BA$4-2,_xlpm.col) + INDEX(_xlpm.rango,$BA$4-1,_xlpm.col) + INDEX(_xlpm.rango,$BA$4, _xlpm.col) )} | G79: {=_xlfn.LET( _xlpm.rango, INDIRECT("N!$C$" & $BA$8 & ":$DR$" & $BA$9), _xlpm.col, G$72+$D78*10, INDEX(_xlpm.rango,$BA$4-3,_xlpm.col) + INDEX(_xlpm.rango,$BA$4-2,_xlpm.col) + INDEX(_xlpm.rango,$BA$4-1,_xlpm.col) + INDEX(_xlpm.rango,$BA$4, _xlpm.col) )} | H79: {=_xlfn.LET( _xlpm.rango, INDIRECT("N!$C$" & $BA$8 & ":$DR$" & $BA$9), _xlpm.col, H$72+$D78*10, INDEX(_xlpm.rango,$BA$4-3,_xlpm.col) + INDEX(_xlpm.rango,$BA$4-2,_xlpm.col) + INDEX(_xlpm.rango,$BA$4-1,_xlpm.col) + INDEX(_xlpm.rango,$BA$4, _xlpm.col) )} | I79: {=_xlfn.LET( _xlpm.rango, INDIRECT("N!$C$" & $BA$8 & ":$DR$" & $BA$9), _xlpm.col, I$72+$D78*10, INDEX(_xlpm.rango,$BA$4-3,_xlpm.col) + INDEX(_xlpm.rango,$BA$4-2,_xlpm.col) + INDEX(_xlpm.rango,$BA$4-1,_xlpm.col) + INDEX(_xlpm.rango,$BA$4, _xlpm.col) )} | J79: {=_xlfn.LET( _xlpm.rango, INDIRECT("N!$C$" & $BA$8 & ":$DR$" & $BA$9), _xlpm.col, J$72+$D78*10, INDEX(_xlpm.rango,$BA$4-3,_xlpm.col) + INDEX(_xlpm.rango,$BA$4-2,_xlpm.col) + INDEX(_xlpm.rango,$BA$4-1,_xlpm.col) + INDEX(_xlpm.rango,$BA$4, _xlpm.col) )} | K79: {=_xlfn.LET( _xlpm.rango, INDIRECT("N!$C$" & $BA$8 & ":$DR$" & $BA$9), _xlpm.col, K$72+$D78*10, INDEX(_xlpm.rango,$BA$4-3,_xlpm.col) + INDEX(_xlpm.rango,$BA$4-2,_xlpm.col) + INDEX(_xlpm.rango,$BA$4-1,_xlpm.col) + INDEX(_xlpm.rango,$BA$4, _xlpm.col) )} | L79: {=_xlfn.LET( _xlpm.rango, INDIRECT("N!$C$" & $BA$8 & ":$DR$" & $BA$9), _xlpm.col, L$72+$D78*10, INDEX(_xlpm.rango,$BA$4-3,_xlpm.col) + INDEX(_xlpm.rango,$BA$4-2,_xlpm.col) + INDEX(_xlpm.rango,$BA$4-1,_xlpm.col) + INDEX(_xlpm.rango,$BA$4, _xlpm.col) )} | M79: {=_xlfn.LET( _xlpm.rango, INDIRECT("N!$C$" & $BA$8 & ":$DR$" & $BA$9), _xlpm.col, M$72+$D78*10, INDEX(_xlpm.rango,$BA$4-3,_xlpm.col) + INDEX(_xlpm.rango,$BA$4-2,_xlpm.col) + INDEX(_xlpm.rango,$BA$4-1,_xlpm.col) + INDEX(_xlpm.rango,$BA$4, _xlpm.col) )} | ... O79: {=_xlfn.LET( _xlpm.rango, INDIRECT("N!$C$" & $BA$8 & ":$DR$" & $BA$9), _xlpm.col, O$72+$D78*10, INDEX(_xlpm.rango,$BA$4-3,_xlpm.col) + INDEX(_xlpm.rango,$BA$4-2,_xlpm.col) + INDEX(_xlpm.rango,$BA$4-1,_xlpm.col) + INDEX(_xlpm.rango,$BA$4, _xlpm.col) )} | P79: {=_xlfn.LET( _xlpm.rango, INDIRECT("S!$C$" & $BA$8 & ":$DR$" & $BA$9), _xlpm.col, P$72+$D78*10, INDEX(_xlpm.rango,$BA$4-3,_xlpm.col) + INDEX(_xlpm.rango,$BA$4-2,_xlpm.col) + INDEX(_xlpm.rango,$BA$4-1,_xlpm.col) + INDEX(_xlpm.rango,$BA$4, _xlpm.col) )} | Q79: {=_xlfn.LET( _xlpm.rango, INDIRECT("S!$C$" & $BA$8 & ":$DR$" & $BA$9), _xlpm.col, Q$72+$D78*10, INDEX(_xlpm.rango,$BA$4-3,_xlpm.col) + INDEX(_xlpm.rango,$BA$4-2,_xlpm.col) + INDEX(_xlpm.rango,$BA$4-1,_xlpm.col) + INDEX(_xlpm.rango,$BA$4, _xlpm.col) )} | R79: {=_xlfn.LET( _xlpm.rango, INDIRECT("S!$C$" & $BA$8 & ":$DR$" & $BA$9), _xlpm.col, R$72+$D78*10, INDEX(_xlpm.rango,$BA$4-3,_xlpm.col) + INDEX(_xlpm.rango,$BA$4-2,_xlpm.col) + INDEX(_xlpm.rango,$BA$4-1,_xlpm.col) + INDEX(_xlpm.rango,$BA$4, _xlpm.col) )} | S79: {=_xlfn.LET( _xlpm.rango, INDIRECT("S!$C$" & $BA$8 & ":$DR$" & $BA$9), _xlpm.col, S$72+$D78*10, INDEX(_xlpm.rango,$BA$4-3,_xlpm.col) + INDEX(_xlpm.rango,$BA$4-2,_xlpm.col) + INDEX(_xlpm.rango,$BA$4-1,_xlpm.col) + INDEX(_xlpm.rango,$BA$4, _xlpm.col) )} | T79: {=_xlfn.LET( _xlpm.rango, INDIRECT("S!$C$" & $BA$8 & ":$DR$" & $BA$9), _xlpm.col, T$72+$D78*10, INDEX(_xlpm.rango,$BA$4-3,_xlpm.col) + INDEX(_xlpm.rango,$BA$4-2,_xlpm.col) + INDEX(_xlpm.rango,$BA$4-1,_xlpm.col) + INDEX(_xlpm.rango,$BA$4, _xlpm.col) )} | U79: {=_xlfn.LET( _xlpm.rango, INDIRECT("S!$C$" & $BA$8 & ":$DR$" & $BA$9), _xlpm.col, U$72+$D78*10, INDEX(_xlpm.rango,$BA$4-3,_xlpm.col) + INDEX(_xlpm.rango,$BA$4-2,_xlpm.col) + INDEX(_xlpm.rango,$BA$4-1,_xlpm.col) + INDEX(_xlpm.rango,$BA$4, _xlpm.col) )} | V79: {=_xlfn.LET( _xlpm.rango, INDIRECT("S!$C$" & $BA$8 & ":$DR$" & $BA$9), _xlpm.col, V$72+$D78*10, INDEX(_xlpm.rango,$BA$4-3,_xlpm.col) + INDEX(_xlpm.rango,$BA$4-2,_xlpm.col) + INDEX(_xlpm.rango,$BA$4-1,_xlpm.col) + INDEX(_xlpm.rango,$BA$4, _xlpm.col) )} | W79: {=_xlfn.LET( _xlpm.rango, INDIRECT("S!$C$" & $BA$8 & ":$DR$" & $BA$9), _xlpm.col, W$72+$D78*10, INDEX(_xlpm.rango,$BA$4-3,_xlpm.col) + INDEX(_xlpm.rango,$BA$4-2,_xlpm.col) + INDEX(_xlpm.rango,$BA$4-1,_xlpm.col) + INDEX(_xlpm.rango,$BA$4, _xlpm.col) )} | ... Y79: {=_xlfn.LET( _xlpm.rango, INDIRECT("S!$C$" & $BA$8 & ":$DR$" & $BA$9), _xlpm.col, Y$72+$D78*10, INDEX(_xlpm.rango,$BA$4-3,_xlpm.col) + INDEX(_xlpm.rango,$BA$4-2,_xlpm.col) + INDEX(_xlpm.rango,$BA$4-1,_xlpm.col) + INDEX(_xlpm.rango,$BA$4, _xlpm.col) )} | Z79: {=_xlfn.LET( _xlpm.rango, INDIRECT("E!$C$" & $BA$8 & ":$DR$" & $BA$9), _xlpm.col, Z$72+$D78*10, INDEX(_xlpm.rango,$BA$4-3,_xlpm.col) + INDEX(_xlpm.rango,$BA$4-2,_xlpm.col) + INDEX(_xlpm.rango,$BA$4-1,_xlpm.col) + INDEX(_xlpm.rango,$BA$4, _xlpm.col) )} | AA79: {=_xlfn.LET( _xlpm.rango, INDIRECT("E!$C$" & $BA$8 & ":$DR$" & $BA$9), _xlpm.col, AA$72+$D78*10, INDEX(_xlpm.rango,$BA$4-3,_xlpm.col) + INDEX(_xlpm.rango,$BA$4-2,_xlpm.col) + INDEX(_xlpm.rango,$BA$4-1,_xlpm.col) + INDEX(_xlpm.rango,$BA$4, _xlpm.col) )} | AB79: {=_xlfn.LET( _xlpm.rango, INDIRECT("E!$C$" & $BA$8 & ":$DR$" & $BA$9), _xlpm.col, AB$72+$D78*10, INDEX(_xlpm.rango,$BA$4-3,_xlpm.col) + INDEX(_xlpm.rango,$BA$4-2,_xlpm.col) + INDEX(_xlpm.rango,$BA$4-1,_xlpm.col) + INDEX(_xlpm.rango,$BA$4, _xlpm.col) )} | AC79: {=_xlfn.LET( _xlpm.rango, INDIRECT("E!$C$" & $BA$8 & ":$DR$" & $BA$9), _xlpm.col, AC$72+$D78*10, INDEX(_xlpm.rango,$BA$4-3,_xlpm.col) + INDEX(_xlpm.rango,$BA$4-2,_xlpm.col) + INDEX(_xlpm.rango,$BA$4-1,_xlpm.col) + INDEX(_xlpm.rango,$BA$4, _xlpm.col) )} | AD79: {=_xlfn.LET( _xlpm.rango, INDIRECT("E!$C$" & $BA$8 & ":$DR$" & $BA$9), _xlpm.col, AD$72+$D78*10, INDEX(_xlpm.rango,$BA$4-3,_xlpm.col) + INDEX(_xlpm.rango,$BA$4-2,_xlpm.col) + INDEX(_xlpm.rango,$BA$4-1,_xlpm.col) + INDEX(_xlpm.rango,$BA$4, _xlpm.col) )} | AE79: {=_xlfn.LET( _xlpm.rango, INDIRECT("E!$C$" & $BA$8 & ":$DR$" & $BA$9), _xlpm.col, AE$72+$D78*10, INDEX(_xlpm.rango,$BA$4-3,_xlpm.col) + INDEX(_xlpm.rango,$BA$4-2,_xlpm.col) + INDEX(_xlpm.rango,$BA$4-1,_xlpm.col) + INDEX(_xlpm.rango,$BA$4, _xlpm.col) )} | AF79: {=_xlfn.LET( _xlpm.rango, INDIRECT("E!$C$" & $BA$8 & ":$DR$" & $BA$9), _xlpm.col, AF$72+$D78*10, INDEX(_xlpm.rango,$BA$4-3,_xlpm.col) + INDEX(_xlpm.rango,$BA$4-2,_xlpm.col) + INDEX(_xlpm.rango,$BA$4-1,_xlpm.col) + INDEX(_xlpm.rango,$BA$4, _xlpm.col) )} | AG79: {=_xlfn.LET( _xlpm.rango, INDIRECT("E!$C$" & $BA$8 & ":$DR$" & $BA$9), _xlpm.col, AG$72+$D78*10, INDEX(_xlpm.rango,$BA$4-3,_xlpm.col) + INDEX(_xlpm.rango,$BA$4-2,_xlpm.col) + INDEX(_xlpm.rango,$BA$4-1,_xlpm.col) + INDEX(_xlpm.rango,$BA$4, _xlpm.col) )} | ... AS79: {=_xlfn.LET( _xlpm.rango, INDIRECT("E!$C$" & $BA$8 & ":$DR$" & $BA$9), _xlpm.col, AS$72+$D78*10, INDEX(_xlpm.rango,$BA$4-3,_xlpm.col) + INDEX(_xlpm.rango,$BA$4-2,_xlpm.col) + INDEX(_xlpm.rango,$BA$4-1,_xlpm.col) + INDEX(_xlpm.rango,$BA$4, _xlpm.col) )} | AT79: =SUM(F79:AS79) | AU79: =AT79/$AT$88
D80: 5 | E80: =Inicio!V8 | F80: {=_xlfn.LET( _xlpm.rango, INDIRECT("N!$C$" & $BA$8 & ":$DR$" & $BA$9), _xlpm.col, F$72+$D79*10, INDEX(_xlpm.rango,$BA$4-3,_xlpm.col) + INDEX(_xlpm.rango,$BA$4-2,_xlpm.col) + INDEX(_xlpm.rango,$BA$4-1,_xlpm.col) + INDEX(_xlpm.rango,$BA$4, _xlpm.col) )} | G80: {=_xlfn.LET( _xlpm.rango, INDIRECT("N!$C$" & $BA$8 & ":$DR$" & $BA$9), _xlpm.col, G$72+$D79*10, INDEX(_xlpm.rango,$BA$4-3,_xlpm.col) + INDEX(_xlpm.rango,$BA$4-2,_xlpm.col) + INDEX(_xlpm.rango,$BA$4-1,_xlpm.col) + INDEX(_xlpm.rango,$BA$4, _xlpm.col) )} | H80: {=_xlfn.LET( _xlpm.rango, INDIRECT("N!$C$" & $BA$8 & ":$DR$" & $BA$9), _xlpm.col, H$72+$D79*10, INDEX(_xlpm.rango,$BA$4-3,_xlpm.col) + INDEX(_xlpm.rango,$BA$4-2,_xlpm.col) + INDEX(_xlpm.rango,$BA$4-1,_xlpm.col) + INDEX(_xlpm.rango,$BA$4, _xlpm.col) )} | I80: {=_xlfn.LET( _xlpm.rango, INDIRECT("N!$C$" & $BA$8 & ":$DR$" & $BA$9), _xlpm.col, I$72+$D79*10, INDEX(_xlpm.rango,$BA$4-3,_xlpm.col) + INDEX(_xlpm.rango,$BA$4-2,_xlpm.col) + INDEX(_xlpm.rango,$BA$4-1,_xlpm.col) + INDEX(_xlpm.rango,$BA$4, _xlpm.col) )} | J80: {=_xlfn.LET( _xlpm.rango, INDIRECT("N!$C$" & $BA$8 & ":$DR$" & $BA$9), _xlpm.col, J$72+$D79*10, INDEX(_xlpm.rango,$BA$4-3,_xlpm.col) + INDEX(_xlpm.rango,$BA$4-2,_xlpm.col) + INDEX(_xlpm.rango,$BA$4-1,_xlpm.col) + INDEX(_xlpm.rango,$BA$4, _xlpm.col) )} | K80: {=_xlfn.LET( _xlpm.rango, INDIRECT("N!$C$" & $BA$8 & ":$DR$" & $BA$9), _xlpm.col, K$72+$D79*10, INDEX(_xlpm.rango,$BA$4-3,_xlpm.col) + INDEX(_xlpm.rango,$BA$4-2,_xlpm.col) + INDEX(_xlpm.rango,$BA$4-1,_xlpm.col) + INDEX(_xlpm.rango,$BA$4, _xlpm.col) )} | L80: {=_xlfn.LET( _xlpm.rango, INDIRECT("N!$C$" & $BA$8 & ":$DR$" & $BA$9), _xlpm.col, L$72+$D79*10, INDEX(_xlpm.rango,$BA$4-3,_xlpm.col) + INDEX(_xlpm.rango,$BA$4-2,_xlpm.col) + INDEX(_xlpm.rango,$BA$4-1,_xlpm.col) + INDEX(_xlpm.rango,$BA$4, _xlpm.col) )} | M80: {=_xlfn.LET( _xlpm.rango, INDIRECT("N!$C$" & $BA$8 & ":$DR$" & $BA$9), _xlpm.col, M$72+$D79*10, INDEX(_xlpm.rango,$BA$4-3,_xlpm.col) + INDEX(_xlpm.rango,$BA$4-2,_xlpm.col) + INDEX(_xlpm.rango,$BA$4-1,_xlpm.col) + INDEX(_xlpm.rango,$BA$4, _xlpm.col) )} | ... O80: {=_xlfn.LET( _xlpm.rango, INDIRECT("N!$C$" & $BA$8 & ":$DR$" & $BA$9), _xlpm.col, O$72+$D79*10, INDEX(_xlpm.rango,$BA$4-3,_xlpm.col) + INDEX(_xlpm.rango,$BA$4-2,_xlpm.col) + INDEX(_xlpm.rango,$BA$4-1,_xlpm.col) + INDEX(_xlpm.rango,$BA$4, _xlpm.col) )} | P80: {=_xlfn.LET( _xlpm.rango, INDIRECT("S!$C$" & $BA$8 & ":$DR$" & $BA$9), _xlpm.col, P$72+$D79*10, INDEX(_xlpm.rango,$BA$4-3,_xlpm.col) + INDEX(_xlpm.rango,$BA$4-2,_xlpm.col) + INDEX(_xlpm.rango,$BA$4-1,_xlpm.col) + INDEX(_xlpm.rango,$BA$4, _xlpm.col) )} | Q80: {=_xlfn.LET( _xlpm.rango, INDIRECT("S!$C$" & $BA$8 & ":$DR$" & $BA$9), _xlpm.col, Q$72+$D79*10, INDEX(_xlpm.rango,$BA$4-3,_xlpm.col) + INDEX(_xlpm.rango,$BA$4-2,_xlpm.col) + INDEX(_xlpm.rango,$BA$4-1,_xlpm.col) + INDEX(_xlpm.rango,$BA$4, _xlpm.col) )} | R80: {=_xlfn.LET( _xlpm.rango, INDIRECT("S!$C$" & $BA$8 & ":$DR$" & $BA$9), _xlpm.col, R$72+$D79*10, INDEX(_xlpm.rango,$BA$4-3,_xlpm.col) + INDEX(_xlpm.rango,$BA$4-2,_xlpm.col) + INDEX(_xlpm.rango,$BA$4-1,_xlpm.col) + INDEX(_xlpm.rango,$BA$4, _xlpm.col) )} | S80: {=_xlfn.LET( _xlpm.rango, INDIRECT("S!$C$" & $BA$8 & ":$DR$" & $BA$9), _xlpm.col, S$72+$D79*10, INDEX(_xlpm.rango,$BA$4-3,_xlpm.col) + INDEX(_xlpm.rango,$BA$4-2,_xlpm.col) + INDEX(_xlpm.rango,$BA$4-1,_xlpm.col) + INDEX(_xlpm.rango,$BA$4, _xlpm.col) )} | T80: {=_xlfn.LET( _xlpm.rango, INDIRECT("S!$C$" & $BA$8 & ":$DR$" & $BA$9), _xlpm.col, T$72+$D79*10, INDEX(_xlpm.rango,$BA$4-3,_xlpm.col) + INDEX(_xlpm.rango,$BA$4-2,_xlpm.col) + INDEX(_xlpm.rango,$BA$4-1,_xlpm.col) + INDEX(_xlpm.rango,$BA$4, _xlpm.col) )} | U80: {=_xlfn.LET( _xlpm.rango, INDIRECT("S!$C$" & $BA$8 & ":$DR$" & $BA$9), _xlpm.col, U$72+$D79*10, INDEX(_xlpm.rango,$BA$4-3,_xlpm.col) + INDEX(_xlpm.rango,$BA$4-2,_xlpm.col) + INDEX(_xlpm.rango,$BA$4-1,_xlpm.col) + INDEX(_xlpm.rango,$BA$4, _xlpm.col) )} | V80: {=_xlfn.LET( _xlpm.rango, INDIRECT("S!$C$" & $BA$8 & ":$DR$" & $BA$9), _xlpm.col, V$72+$D79*10, INDEX(_xlpm.rango,$BA$4-3,_xlpm.col) + INDEX(_xlpm.rango,$BA$4-2,_xlpm.col) + INDEX(_xlpm.rango,$BA$4-1,_xlpm.col) + INDEX(_xlpm.rango,$BA$4, _xlpm.col) )} | W80: {=_xlfn.LET( _xlpm.rango, INDIRECT("S!$C$" & $BA$8 & ":$DR$" & $BA$9), _xlpm.col, W$72+$D79*10, INDEX(_xlpm.rango,$BA$4-3,_xlpm.col) + INDEX(_xlpm.rango,$BA$4-2,_xlpm.col) + INDEX(_xlpm.rango,$BA$4-1,_xlpm.col) + INDEX(_xlpm.rango,$BA$4, _xlpm.col) )} | ... Y80: {=_xlfn.LET( _xlpm.rango, INDIRECT("S!$C$" & $BA$8 & ":$DR$" & $BA$9), _xlpm.col, Y$72+$D79*10, INDEX(_xlpm.rango,$BA$4-3,_xlpm.col) + INDEX(_xlpm.rango,$BA$4-2,_xlpm.col) + INDEX(_xlpm.rango,$BA$4-1,_xlpm.col) + INDEX(_xlpm.rango,$BA$4, _xlpm.col) )} | Z80: {=_xlfn.LET( _xlpm.rango, INDIRECT("E!$C$" & $BA$8 & ":$DR$" & $BA$9), _xlpm.col, Z$72+$D79*10, INDEX(_xlpm.rango,$BA$4-3,_xlpm.col) + INDEX(_xlpm.rango,$BA$4-2,_xlpm.col) + INDEX(_xlpm.rango,$BA$4-1,_xlpm.col) + INDEX(_xlpm.rango,$BA$4, _xlpm.col) )} | AA80: {=_xlfn.LET( _xlpm.rango, INDIRECT("E!$C$" & $BA$8 & ":$DR$" & $BA$9), _xlpm.col, AA$72+$D79*10, INDEX(_xlpm.rango,$BA$4-3,_xlpm.col) + INDEX(_xlpm.rango,$BA$4-2,_xlpm.col) + INDEX(_xlpm.rango,$BA$4-1,_xlpm.col) + INDEX(_xlpm.rango,$BA$4, _xlpm.col) )} | AB80: {=_xlfn.LET( _xlpm.rango, INDIRECT("E!$C$" & $BA$8 & ":$DR$" & $BA$9), _xlpm.col, AB$72+$D79*10, INDEX(_xlpm.rango,$BA$4-3,_xlpm.col) + INDEX(_xlpm.rango,$BA$4-2,_xlpm.col) + INDEX(_xlpm.rango,$BA$4-1,_xlpm.col) + INDEX(_xlpm.rango,$BA$4, _xlpm.col) )} | AC80: {=_xlfn.LET( _xlpm.rango, INDIRECT("E!$C$" & $BA$8 & ":$DR$" & $BA$9), _xlpm.col, AC$72+$D79*10, INDEX(_xlpm.rango,$BA$4-3,_xlpm.col) + INDEX(_xlpm.rango,$BA$4-2,_xlpm.col) + INDEX(_xlpm.rango,$BA$4-1,_xlpm.col) + INDEX(_xlpm.rango,$BA$4, _xlpm.col) )} | AD80: {=_xlfn.LET( _xlpm.rango, INDIRECT("E!$C$" & $BA$8 & ":$DR$" & $BA$9), _xlpm.col, AD$72+$D79*10, INDEX(_xlpm.rango,$BA$4-3,_xlpm.col) + INDEX(_xlpm.rango,$BA$4-2,_xlpm.col) + INDEX(_xlpm.rango,$BA$4-1,_xlpm.col) + INDEX(_xlpm.rango,$BA$4, _xlpm.col) )} | AE80: {=_xlfn.LET( _xlpm.rango, INDIRECT("E!$C$" & $BA$8 & ":$DR$" & $BA$9), _xlpm.col, AE$72+$D79*10, INDEX(_xlpm.rango,$BA$4-3,_xlpm.col) + INDEX(_xlpm.rango,$BA$4-2,_xlpm.col) + INDEX(_xlpm.rango,$BA$4-1,_xlpm.col) + INDEX(_xlpm.rango,$BA$4, _xlpm.col) )} | AF80: {=_xlfn.LET( _xlpm.rango, INDIRECT("E!$C$" & $BA$8 & ":$DR$" & $BA$9), _xlpm.col, AF$72+$D79*10, INDEX(_xlpm.rango,$BA$4-3,_xlpm.col) + INDEX(_xlpm.rango,$BA$4-2,_xlpm.col) + INDEX(_xlpm.rango,$BA$4-1,_xlpm.col) + INDEX(_xlpm.rango,$BA$4, _xlpm.col) )} | AG80: {=_xlfn.LET( _xlpm.rango, INDIRECT("E!$C$" & $BA$8 & ":$DR$" & $BA$9), _xlpm.col, AG$72+$D79*10, INDEX(_xlpm.rango,$BA$4-3,_xlpm.col) + INDEX(_xlpm.rango,$BA$4-2,_xlpm.col) + INDEX(_xlpm.rango,$BA$4-1,_xlpm.col) + INDEX(_xlpm.rango,$BA$4, _xlpm.col) )} | ... AS80: {=_xlfn.LET( _xlpm.rango, INDIRECT("E!$C$" & $BA$8 & ":$DR$" & $BA$9), _xlpm.col, AS$72+$D79*10, INDEX(_xlpm.rango,$BA$4-3,_xlpm.col) + INDEX(_xlpm.rango,$BA$4-2,_xlpm.col) + INDEX(_xlpm.rango,$BA$4-1,_xlpm.col) + INDEX(_xlpm.rango,$BA$4, _xlpm.col) )} | AT80: =SUM(F80:AS80) | AU80: =AT80/$AT$88
D81: 6 | E81: =Inicio!V9 | F81: {=_xlfn.LET( _xlpm.rango, INDIRECT("N!$C$" & $BA$8 & ":$DR$" & $BA$9), _xlpm.col, F$72+$D80*10, INDEX(_xlpm.rango,$BA$4-3,_xlpm.col) + INDEX(_xlpm.rango,$BA$4-2,_xlpm.col) + INDEX(_xlpm.rango,$BA$4-1,_xlpm.col) + INDEX(_xlpm.rango,$BA$4, _xlpm.col) )} | G81: {=_xlfn.LET( _xlpm.rango, INDIRECT("N!$C$" & $BA$8 & ":$DR$" & $BA$9), _xlpm.col, G$72+$D80*10, INDEX(_xlpm.rango,$BA$4-3,_xlpm.col) + INDEX(_xlpm.rango,$BA$4-2,_xlpm.col) + INDEX(_xlpm.rango,$BA$4-1,_xlpm.col) + INDEX(_xlpm.rango,$BA$4, _xlpm.col) )} | H81: {=_xlfn.LET( _xlpm.rango, INDIRECT("N!$C$" & $BA$8 & ":$DR$" & $BA$9), _xlpm.col, H$72+$D80*10, INDEX(_xlpm.rango,$BA$4-3,_xlpm.col) + INDEX(_xlpm.rango,$BA$4-2,_xlpm.col) + INDEX(_xlpm.rango,$BA$4-1,_xlpm.col) + INDEX(_xlpm.rango,$BA$4, _xlpm.col) )} | I81: {=_xlfn.LET( _xlpm.rango, INDIRECT("N!$C$" & $BA$8 & ":$DR$" & $BA$9), _xlpm.col, I$72+$D80*10, INDEX(_xlpm.rango,$BA$4-3,_xlpm.col) + INDEX(_xlpm.rango,$BA$4-2,_xlpm.col) + INDEX(_xlpm.rango,$BA$4-1,_xlpm.col) + INDEX(_xlpm.rango,$BA$4, _xlpm.col) )} | J81: {=_xlfn.LET( _xlpm.rango, INDIRECT("N!$C$" & $BA$8 & ":$DR$" & $BA$9), _xlpm.col, J$72+$D80*10, INDEX(_xlpm.rango,$BA$4-3,_xlpm.col) + INDEX(_xlpm.rango,$BA$4-2,_xlpm.col) + INDEX(_xlpm.rango,$BA$4-1,_xlpm.col) + INDEX(_xlpm.rango,$BA$4, _xlpm.col) )} | K81: {=_xlfn.LET( _xlpm.rango, INDIRECT("N!$C$" & $BA$8 & ":$DR$" & $BA$9), _xlpm.col, K$72+$D80*10, INDEX(_xlpm.rango,$BA$4-3,_xlpm.col) + INDEX(_xlpm.rango,$BA$4-2,_xlpm.col) + INDEX(_xlpm.rango,$BA$4-1,_xlpm.col) + INDEX(_xlpm.rango,$BA$4, _xlpm.col) )} | L81: {=_xlfn.LET( _xlpm.rango, INDIRECT("N!$C$" & $BA$8 & ":$DR$" & $BA$9), _xlpm.col, L$72+$D80*10, INDEX(_xlpm.rango,$BA$4-3,_xlpm.col) + INDEX(_xlpm.rango,$BA$4-2,_xlpm.col) + INDEX(_xlpm.rango,$BA$4-1,_xlpm.col) + INDEX(_xlpm.rango,$BA$4, _xlpm.col) )} | M81: {=_xlfn.LET( _xlpm.rango, INDIRECT("N!$C$" & $BA$8 & ":$DR$" & $BA$9), _xlpm.col, M$72+$D80*10, INDEX(_xlpm.rango,$BA$4-3,_xlpm.col) + INDEX(_xlpm.rango,$BA$4-2,_xlpm.col) + INDEX(_xlpm.rango,$BA$4-1,_xlpm.col) + INDEX(_xlpm.rango,$BA$4, _xlpm.col) )} | ... O81: {=_xlfn.LET( _xlpm.rango, INDIRECT("N!$C$" & $BA$8 & ":$DR$" & $BA$9), _xlpm.col, O$72+$D80*10, INDEX(_xlpm.rango,$BA$4-3,_xlpm.col) + INDEX(_xlpm.rango,$BA$4-2,_xlpm.col) + INDEX(_xlpm.rango,$BA$4-1,_xlpm.col) + INDEX(_xlpm.rango,$BA$4, _xlpm.col) )} | P81: {=_xlfn.LET( _xlpm.rango, INDIRECT("S!$C$" & $BA$8 & ":$DR$" & $BA$9), _xlpm.col, P$72+$D80*10, INDEX(_xlpm.rango,$BA$4-3,_xlpm.col) + INDEX(_xlpm.rango,$BA$4-2,_xlpm.col) + INDEX(_xlpm.rango,$BA$4-1,_xlpm.col) + INDEX(_xlpm.rango,$BA$4, _xlpm.col) )} | Q81: {=_xlfn.LET( _xlpm.rango, INDIRECT("S!$C$" & $BA$8 & ":$DR$" & $BA$9), _xlpm.col, Q$72+$D80*10, INDEX(_xlpm.rango,$BA$4-3,_xlpm.col) + INDEX(_xlpm.rango,$BA$4-2,_xlpm.col) + INDEX(_xlpm.rango,$BA$4-1,_xlpm.col) + INDEX(_xlpm.rango,$BA$4, _xlpm.col) )} | R81: {=_xlfn.LET( _xlpm.rango, INDIRECT("S!$C$" & $BA$8 & ":$DR$" & $BA$9), _xlpm.col, R$72+$D80*10, INDEX(_xlpm.rango,$BA$4-3,_xlpm.col) + INDEX(_xlpm.rango,$BA$4-2,_xlpm.col) + INDEX(_xlpm.rango,$BA$4-1,_xlpm.col) + INDEX(_xlpm.rango,$BA$4, _xlpm.col) )} | S81: {=_xlfn.LET( _xlpm.rango, INDIRECT("S!$C$" & $BA$8 & ":$DR$" & $BA$9), _xlpm.col, S$72+$D80*10, INDEX(_xlpm.rango,$BA$4-3,_xlpm.col) + INDEX(_xlpm.rango,$BA$4-2,_xlpm.col) + INDEX(_xlpm.rango,$BA$4-1,_xlpm.col) + INDEX(_xlpm.rango,$BA$4, _xlpm.col) )} | T81: {=_xlfn.LET( _xlpm.rango, INDIRECT("S!$C$" & $BA$8 & ":$DR$" & $BA$9), _xlpm.col, T$72+$D80*10, INDEX(_xlpm.rango,$BA$4-3,_xlpm.col) + INDEX(_xlpm.rango,$BA$4-2,_xlpm.col) + INDEX(_xlpm.rango,$BA$4-1,_xlpm.col) + INDEX(_xlpm.rango,$BA$4, _xlpm.col) )} | U81: {=_xlfn.LET( _xlpm.rango, INDIRECT("S!$C$" & $BA$8 & ":$DR$" & $BA$9), _xlpm.col, U$72+$D80*10, INDEX(_xlpm.rango,$BA$4-3,_xlpm.col) + INDEX(_xlpm.rango,$BA$4-2,_xlpm.col) + INDEX(_xlpm.rango,$BA$4-1,_xlpm.col) + INDEX(_xlpm.rango,$BA$4, _xlpm.col) )} | V81: {=_xlfn.LET( _xlpm.rango, INDIRECT("S!$C$" & $BA$8 & ":$DR$" & $BA$9), _xlpm.col, V$72+$D80*10, INDEX(_xlpm.rango,$BA$4-3,_xlpm.col) + INDEX(_xlpm.rango,$BA$4-2,_xlpm.col) + INDEX(_xlpm.rango,$BA$4-1,_xlpm.col) + INDEX(_xlpm.rango,$BA$4, _xlpm.col) )} | W81: {=_xlfn.LET( _xlpm.rango, INDIRECT("S!$C$" & $BA$8 & ":$DR$" & $BA$9), _xlpm.col, W$72+$D80*10, INDEX(_xlpm.rango,$BA$4-3,_xlpm.col) + INDEX(_xlpm.rango,$BA$4-2,_xlpm.col) + INDEX(_xlpm.rango,$BA$4-1,_xlpm.col) + INDEX(_xlpm.rango,$BA$4, _xlpm.col) )} | ... Y81: {=_xlfn.LET( _xlpm.rango, INDIRECT("S!$C$" & $BA$8 & ":$DR$" & $BA$9), _xlpm.col, Y$72+$D80*10, INDEX(_xlpm.rango,$BA$4-3,_xlpm.col) + INDEX(_xlpm.rango,$BA$4-2,_xlpm.col) + INDEX(_xlpm.rango,$BA$4-1,_xlpm.col) + INDEX(_xlpm.rango,$BA$4, _xlpm.col) )} | Z81: {=_xlfn.LET( _xlpm.rango, INDIRECT("E!$C$" & $BA$8 & ":$DR$" & $BA$9), _xlpm.col, Z$72+$D80*10, INDEX(_xlpm.rango,$BA$4-3,_xlpm.col) + INDEX(_xlpm.rango,$BA$4-2,_xlpm.col) + INDEX(_xlpm.rango,$BA$4-1,_xlpm.col) + INDEX(_xlpm.rango,$BA$4, _xlpm.col) )} | AA81: {=_xlfn.LET( _xlpm.rango, INDIRECT("E!$C$" & $BA$8 & ":$DR$" & $BA$9), _xlpm.col, AA$72+$D80*10, INDEX(_xlpm.rango,$BA$4-3,_xlpm.col) + INDEX(_xlpm.rango,$BA$4-2,_xlpm.col) + INDEX(_xlpm.rango,$BA$4-1,_xlpm.col) + INDEX(_xlpm.rango,$BA$4, _xlpm.col) )} | AB81: {=_xlfn.LET( _xlpm.rango, INDIRECT("E!$C$" & $BA$8 & ":$DR$" & $BA$9), _xlpm.col, AB$72+$D80*10, INDEX(_xlpm.rango,$BA$4-3,_xlpm.col) + INDEX(_xlpm.rango,$BA$4-2,_xlpm.col) + INDEX(_xlpm.rango,$BA$4-1,_xlpm.col) + INDEX(_xlpm.rango,$BA$4, _xlpm.col) )} | AC81: {=_xlfn.LET( _xlpm.rango, INDIRECT("E!$C$" & $BA$8 & ":$DR$" & $BA$9), _xlpm.col, AC$72+$D80*10, INDEX(_xlpm.rango,$BA$4-3,_xlpm.col) + INDEX(_xlpm.rango,$BA$4-2,_xlpm.col) + INDEX(_xlpm.rango,$BA$4-1,_xlpm.col) + INDEX(_xlpm.rango,$BA$4, _xlpm.col) )} | AD81: {=_xlfn.LET( _xlpm.rango, INDIRECT("E!$C$" & $BA$8 & ":$DR$" & $BA$9), _xlpm.col, AD$72+$D80*10, INDEX(_xlpm.rango,$BA$4-3,_xlpm.col) + INDEX(_xlpm.rango,$BA$4-2,_xlpm.col) + INDEX(_xlpm.rango,$BA$4-1,_xlpm.col) + INDEX(_xlpm.rango,$BA$4, _xlpm.col) )} | AE81: {=_xlfn.LET( _xlpm.rango, INDIRECT("E!$C$" & $BA$8 & ":$DR$" & $BA$9), _xlpm.col, AE$72+$D80*10, INDEX(_xlpm.rango,$BA$4-3,_xlpm.col) + INDEX(_xlpm.rango,$BA$4-2,_xlpm.col) + INDEX(_xlpm.rango,$BA$4-1,_xlpm.col) + INDEX(_xlpm.rango,$BA$4, _xlpm.col) )} | AF81: {=_xlfn.LET( _xlpm.rango, INDIRECT("E!$C$" & $BA$8 & ":$DR$" & $BA$9), _xlpm.col, AF$72+$D80*10, INDEX(_xlpm.rango,$BA$4-3,_xlpm.col) + INDEX(_xlpm.rango,$BA$4-2,_xlpm.col) + INDEX(_xlpm.rango,$BA$4-1,_xlpm.col) + INDEX(_xlpm.rango,$BA$4, _xlpm.col) )} | AG81: {=_xlfn.LET( _xlpm.rango, INDIRECT("E!$C$" & $BA$8 & ":$DR$" & $BA$9), _xlpm.col, AG$72+$D80*10, INDEX(_xlpm.rango,$BA$4-3,_xlpm.col) + INDEX(_xlpm.rango,$BA$4-2,_xlpm.col) + INDEX(_xlpm.rango,$BA$4-1,_xlpm.col) + INDEX(_xlpm.rango,$BA$4, _xlpm.col) )} | ... AS81: {=_xlfn.LET( _xlpm.rango, INDIRECT("E!$C$" & $BA$8 & ":$DR$" & $BA$9), _xlpm.col, AS$72+$D80*10, INDEX(_xlpm.rango,$BA$4-3,_xlpm.col) + INDEX(_xlpm.rango,$BA$4-2,_xlpm.col) + INDEX(_xlpm.rango,$BA$4-1,_xlpm.col) + INDEX(_xlpm.rango,$BA$4, _xlpm.col) )} | AT81: =SUM(F81:AS81) | AU81: =AT81/$AT$88
D82: 7 | E82: =Inicio!V10 | F82: {=_xlfn.LET( _xlpm.rango, INDIRECT("N!$C$" & $BA$8 & ":$DR$" & $BA$9), _xlpm.col, F$72+$D81*10, INDEX(_xlpm.rango,$BA$4-3,_xlpm.col) + INDEX(_xlpm.rango,$BA$4-2,_xlpm.col) + INDEX(_xlpm.rango,$BA$4-1,_xlpm.col) + INDEX(_xlpm.rango,$BA$4, _xlpm.col) )} | G82: {=_xlfn.LET( _xlpm.rango, INDIRECT("N!$C$" & $BA$8 & ":$DR$" & $BA$9), _xlpm.col, G$72+$D81*10, INDEX(_xlpm.rango,$BA$4-3,_xlpm.col) + INDEX(_xlpm.rango,$BA$4-2,_xlpm.col) + INDEX(_xlpm.rango,$BA$4-1,_xlpm.col) + INDEX(_xlpm.rango,$BA$4, _xlpm.col) )} | H82: {=_xlfn.LET( _xlpm.rango, INDIRECT("N!$C$" & $BA$8 & ":$DR$" & $BA$9), _xlpm.col, H$72+$D81*10, INDEX(_xlpm.rango,$BA$4-3,_xlpm.col) + INDEX(_xlpm.rango,$BA$4-2,_xlpm.col) + INDEX(_xlpm.rango,$BA$4-1,_xlpm.col) + INDEX(_xlpm.rango,$BA$4, _xlpm.col) )} | I82: {=_xlfn.LET( _xlpm.rango, INDIRECT("N!$C$" & $BA$8 & ":$DR$" & $BA$9), _xlpm.col, I$72+$D81*10, INDEX(_xlpm.rango,$BA$4-3,_xlpm.col) + INDEX(_xlpm.rango,$BA$4-2,_xlpm.col) + INDEX(_xlpm.rango,$BA$4-1,_xlpm.col) + INDEX(_xlpm.rango,$BA$4, _xlpm.col) )} | J82: {=_xlfn.LET( _xlpm.rango, INDIRECT("N!$C$" & $BA$8 & ":$DR$" & $BA$9), _xlpm.col, J$72+$D81*10, INDEX(_xlpm.rango,$BA$4-3,_xlpm.col) + INDEX(_xlpm.rango,$BA$4-2,_xlpm.col) + INDEX(_xlpm.rango,$BA$4-1,_xlpm.col) + INDEX(_xlpm.rango,$BA$4, _xlpm.col) )} | K82: {=_xlfn.LET( _xlpm.rango, INDIRECT("N!$C$" & $BA$8 & ":$DR$" & $BA$9), _xlpm.col, K$72+$D81*10, INDEX(_xlpm.rango,$BA$4-3,_xlpm.col) + INDEX(_xlpm.rango,$BA$4-2,_xlpm.col) + INDEX(_xlpm.rango,$BA$4-1,_xlpm.col) + INDEX(_xlpm.rango,$BA$4, _xlpm.col) )} | L82: {=_xlfn.LET( _xlpm.rango, INDIRECT("N!$C$" & $BA$8 & ":$DR$" & $BA$9), _xlpm.col, L$72+$D81*10, INDEX(_xlpm.rango,$BA$4-3,_xlpm.col) + INDEX(_xlpm.rango,$BA$4-2,_xlpm.col) + INDEX(_xlpm.rango,$BA$4-1,_xlpm.col) + INDEX(_xlpm.rango,$BA$4, _xlpm.col) )} | M82: {=_xlfn.LET( _xlpm.rango, INDIRECT("N!$C$" & $BA$8 & ":$DR$" & $BA$9), _xlpm.col, M$72+$D81*10, INDEX(_xlpm.rango,$BA$4-3,_xlpm.col) + INDEX(_xlpm.rango,$BA$4-2,_xlpm.col) + INDEX(_xlpm.rango,$BA$4-1,_xlpm.col) + INDEX(_xlpm.rango,$BA$4, _xlpm.col) )} | ... O82: {=_xlfn.LET( _xlpm.rango, INDIRECT("N!$C$" & $BA$8 & ":$DR$" & $BA$9), _xlpm.col, O$72+$D81*10, INDEX(_xlpm.rango,$BA$4-3,_xlpm.col) + INDEX(_xlpm.rango,$BA$4-2,_xlpm.col) + INDEX(_xlpm.rango,$BA$4-1,_xlpm.col) + INDEX(_xlpm.rango,$BA$4, _xlpm.col) )} | P82: {=_xlfn.LET( _xlpm.rango, INDIRECT("S!$C$" & $BA$8 & ":$DR$" & $BA$9), _xlpm.col, P$72+$D81*10, INDEX(_xlpm.rango,$BA$4-3,_xlpm.col) + INDEX(_xlpm.rango,$BA$4-2,_xlpm.col) + INDEX(_xlpm.rango,$BA$4-1,_xlpm.col) + INDEX(_xlpm.rango,$BA$4, _xlpm.col) )} | Q82: {=_xlfn.LET( _xlpm.rango, INDIRECT("S!$C$" & $BA$8 & ":$DR$" & $BA$9), _xlpm.col, Q$72+$D81*10, INDEX(_xlpm.rango,$BA$4-3,_xlpm.col) + INDEX(_xlpm.rango,$BA$4-2,_xlpm.col) + INDEX(_xlpm.rango,$BA$4-1,_xlpm.col) + INDEX(_xlpm.rango,$BA$4, _xlpm.col) )} | R82: {=_xlfn.LET( _xlpm.rango, INDIRECT("S!$C$" & $BA$8 & ":$DR$" & $BA$9), _xlpm.col, R$72+$D81*10, INDEX(_xlpm.rango,$BA$4-3,_xlpm.col) + INDEX(_xlpm.rango,$BA$4-2,_xlpm.col) + INDEX(_xlpm.rango,$BA$4-1,_xlpm.col) + INDEX(_xlpm.rango,$BA$4, _xlpm.col) )} | S82: {=_xlfn.LET( _xlpm.rango, INDIRECT("S!$C$" & $BA$8 & ":$DR$" & $BA$9), _xlpm.col, S$72+$D81*10, INDEX(_xlpm.rango,$BA$4-3,_xlpm.col) + INDEX(_xlpm.rango,$BA$4-2,_xlpm.col) + INDEX(_xlpm.rango,$BA$4-1,_xlpm.col) + INDEX(_xlpm.rango,$BA$4, _xlpm.col) )} | T82: {=_xlfn.LET( _xlpm.rango, INDIRECT("S!$C$" & $BA$8 & ":$DR$" & $BA$9), _xlpm.col, T$72+$D81*10, INDEX(_xlpm.rango,$BA$4-3,_xlpm.col) + INDEX(_xlpm.rango,$BA$4-2,_xlpm.col) + INDEX(_xlpm.rango,$BA$4-1,_xlpm.col) + INDEX(_xlpm.rango,$BA$4, _xlpm.col) )} | U82: {=_xlfn.LET( _xlpm.rango, INDIRECT("S!$C$" & $BA$8 & ":$DR$" & $BA$9), _xlpm.col, U$72+$D81*10, INDEX(_xlpm.rango,$BA$4-3,_xlpm.col) + INDEX(_xlpm.rango,$BA$4-2,_xlpm.col) + INDEX(_xlpm.rango,$BA$4-1,_xlpm.col) + INDEX(_xlpm.rango,$BA$4, _xlpm.col) )} | V82: {=_xlfn.LET( _xlpm.rango, INDIRECT("S!$C$" & $BA$8 & ":$DR$" & $BA$9), _xlpm.col, V$72+$D81*10, INDEX(_xlpm.rango,$BA$4-3,_xlpm.col) + INDEX(_xlpm.rango,$BA$4-2,_xlpm.col) + INDEX(_xlpm.rango,$BA$4-1,_xlpm.col) + INDEX(_xlpm.rango,$BA$4, _xlpm.col) )} | W82: {=_xlfn.LET( _xlpm.rango, INDIRECT("S!$C$" & $BA$8 & ":$DR$" & $BA$9), _xlpm.col, W$72+$D81*10, INDEX(_xlpm.rango,$BA$4-3,_xlpm.col) + INDEX(_xlpm.rango,$BA$4-2,_xlpm.col) + INDEX(_xlpm.rango,$BA$4-1,_xlpm.col) + INDEX(_xlpm.rango,$BA$4, _xlpm.col) )} | ... Y82: {=_xlfn.LET( _xlpm.rango, INDIRECT("S!$C$" & $BA$8 & ":$DR$" & $BA$9), _xlpm.col, Y$72+$D81*10, INDEX(_xlpm.rango,$BA$4-3,_xlpm.col) + INDEX(_xlpm.rango,$BA$4-2,_xlpm.col) + INDEX(_xlpm.rango,$BA$4-1,_xlpm.col) + INDEX(_xlpm.rango,$BA$4, _xlpm.col) )} | Z82: {=_xlfn.LET( _xlpm.rango, INDIRECT("E!$C$" & $BA$8 & ":$DR$" & $BA$9), _xlpm.col, Z$72+$D81*10, INDEX(_xlpm.rango,$BA$4-3,_xlpm.col) + INDEX(_xlpm.rango,$BA$4-2,_xlpm.col) + INDEX(_xlpm.rango,$BA$4-1,_xlpm.col) + INDEX(_xlpm.rango,$BA$4, _xlpm.col) )} | AA82: {=_xlfn.LET( _xlpm.rango, INDIRECT("E!$C$" & $BA$8 & ":$DR$" & $BA$9), _xlpm.col, AA$72+$D81*10, INDEX(_xlpm.rango,$BA$4-3,_xlpm.col) + INDEX(_xlpm.rango,$BA$4-2,_xlpm.col) + INDEX(_xlpm.rango,$BA$4-1,_xlpm.col) + INDEX(_xlpm.rango,$BA$4, _xlpm.col) )} | AB82: {=_xlfn.LET( _xlpm.rango, INDIRECT("E!$C$" & $BA$8 & ":$DR$" & $BA$9), _xlpm.col, AB$72+$D81*10, INDEX(_xlpm.rango,$BA$4-3,_xlpm.col) + INDEX(_xlpm.rango,$BA$4-2,_xlpm.col) + INDEX(_xlpm.rango,$BA$4-1,_xlpm.col) + INDEX(_xlpm.rango,$BA$4, _xlpm.col) )} | AC82: {=_xlfn.LET( _xlpm.rango, INDIRECT("E!$C$" & $BA$8 & ":$DR$" & $BA$9), _xlpm.col, AC$72+$D81*10, INDEX(_xlpm.rango,$BA$4-3,_xlpm.col) + INDEX(_xlpm.rango,$BA$4-2,_xlpm.col) + INDEX(_xlpm.rango,$BA$4-1,_xlpm.col) + INDEX(_xlpm.rango,$BA$4, _xlpm.col) )} | AD82: {=_xlfn.LET( _xlpm.rango, INDIRECT("E!$C$" & $BA$8 & ":$DR$" & $BA$9), _xlpm.col, AD$72+$D81*10, INDEX(_xlpm.rango,$BA$4-3,_xlpm.col) + INDEX(_xlpm.rango,$BA$4-2,_xlpm.col) + INDEX(_xlpm.rango,$BA$4-1,_xlpm.col) + INDEX(_xlpm.rango,$BA$4, _xlpm.col) )} | AE82: {=_xlfn.LET( _xlpm.rango, INDIRECT("E!$C$" & $BA$8 & ":$DR$" & $BA$9), _xlpm.col, AE$72+$D81*10, INDEX(_xlpm.rango,$BA$4-3,_xlpm.col) + INDEX(_xlpm.rango,$BA$4-2,_xlpm.col) + INDEX(_xlpm.rango,$BA$4-1,_xlpm.col) + INDEX(_xlpm.rango,$BA$4, _xlpm.col) )} | AF82: {=_xlfn.LET( _xlpm.rango, INDIRECT("E!$C$" & $BA$8 & ":$DR$" & $BA$9), _xlpm.col, AF$72+$D81*10, INDEX(_xlpm.rango,$BA$4-3,_xlpm.col) + INDEX(_xlpm.rango,$BA$4-2,_xlpm.col) + INDEX(_xlpm.rango,$BA$4-1,_xlpm.col) + INDEX(_xlpm.rango,$BA$4, _xlpm.col) )} | AG82: {=_xlfn.LET( _xlpm.rango, INDIRECT("E!$C$" & $BA$8 & ":$DR$" & $BA$9), _xlpm.col, AG$72+$D81*10, INDEX(_xlpm.rango,$BA$4-3,_xlpm.col) + INDEX(_xlpm.rango,$BA$4-2,_xlpm.col) + INDEX(_xlpm.rango,$BA$4-1,_xlpm.col) + INDEX(_xlpm.rango,$BA$4, _xlpm.col) )} | ... AS82: {=_xlfn.LET( _xlpm.rango, INDIRECT("E!$C$" & $BA$8 & ":$DR$" & $BA$9), _xlpm.col, AS$72+$D81*10, INDEX(_xlpm.rango,$BA$4-3,_xlpm.col) + INDEX(_xlpm.rango,$BA$4-2,_xlpm.col) + INDEX(_xlpm.rango,$BA$4-1,_xlpm.col) + INDEX(_xlpm.rango,$BA$4, _xlpm.col) )} | AT82: =SUM(F82:AS82) | AU82: =AT82/$AT$88
